nohup: ignoring input
2023-11-25 21:17:56,787	WARNING deprecation.py:50 -- DeprecationWarning: `DirectStepOptimizer` has been deprecated. This will raise an error in the future!
2023-11-25 21:18:02,040	INFO worker.py:1612 -- Started a local Ray instance. View the dashboard at [1m[32m127.0.0.1:8266 [39m[22m
2023-11-25 21:18:06,906	WARNING algorithm_config.py:2558 -- Setting `exploration_config={}` because you set `_enable_rl_module_api=True`. When RLModule API are enabled, exploration_config can not be set. If you want to implement custom exploration behaviour, please modify the `forward_exploration` method of the RLModule at hand. On configs that have a default exploration config, this must be done with `config.exploration_config={}`.
2023-11-25 21:18:06,923	INFO tune.py:666 -- [output] This will use the new output engine with verbosity 1. To disable the new output and use the legacy output engine, set the environment variable RAY_AIR_NEW_OUTPUT=0. For more information, please see https://github.com/ray-project/ray/issues/36949
2023-11-25 21:18:06,940	WARNING deprecation.py:50 -- DeprecationWarning: `build_tf_policy` has been deprecated. This will raise an error in the future!
2023-11-25 21:18:06,948	WARNING deprecation.py:50 -- DeprecationWarning: `build_policy_class` has been deprecated. This will raise an error in the future!
2023-11-25 21:18:07,033	WARNING algorithm_config.py:2558 -- Setting `exploration_config={}` because you set `_enable_rl_module_api=True`. When RLModule API are enabled, exploration_config can not be set. If you want to implement custom exploration behaviour, please modify the `forward_exploration` method of the RLModule at hand. On configs that have a default exploration config, this must be done with `config.exploration_config={}`.
/home/ezhao/miniconda3/envs/MARL/lib/python3.9/site-packages/gymnasium/spaces/box.py:130: UserWarning: [33mWARN: Box bound precision lowered by casting to float32[0m
  gym.logger.warn(f"Box bound precision lowered by casting to {self.dtype}")
/home/ezhao/miniconda3/envs/MARL/lib/python3.9/site-packages/gymnasium/utils/passive_env_checker.py:164: UserWarning: [33mWARN: The obs returned by the `reset()` method was expecting numpy array dtype to be float32, actual type: float64[0m
  logger.warn(
/home/ezhao/miniconda3/envs/MARL/lib/python3.9/site-packages/gymnasium/utils/passive_env_checker.py:188: UserWarning: [33mWARN: The obs returned by the `reset()` method is not within the observation space.[0m
  logger.warn(f"{pre} is not within the observation space.")
2023-11-25 21:18:07,293	WARNING algorithm_config.py:2558 -- Setting `exploration_config={}` because you set `_enable_rl_module_api=True`. When RLModule API are enabled, exploration_config can not be set. If you want to implement custom exploration behaviour, please modify the `forward_exploration` method of the RLModule at hand. On configs that have a default exploration config, this must be done with `config.exploration_config={}`.
2023-11-25 21:18:07,362	WARNING algorithm_config.py:2558 -- Setting `exploration_config={}` because you set `_enable_rl_module_api=True`. When RLModule API are enabled, exploration_config can not be set. If you want to implement custom exploration behaviour, please modify the `forward_exploration` method of the RLModule at hand. On configs that have a default exploration config, this must be done with `config.exploration_config={}`.
[2m[36m(pid=2647792)[0m DeprecationWarning: `DirectStepOptimizer` has been deprecated. This will raise an error in the future!
[2m[36m(PPO pid=2647792)[0m 2023-11-25 21:18:32,140	WARNING algorithm_config.py:2558 -- Setting `exploration_config={}` because you set `_enable_rl_module_api=True`. When RLModule API are enabled, exploration_config can not be set. If you want to implement custom exploration behaviour, please modify the `forward_exploration` method of the RLModule at hand. On configs that have a default exploration config, this must be done with `config.exploration_config={}`.
[2m[36m(PPO pid=2647792)[0m 2023-11-25 21:18:32,141	WARNING algorithm_config.py:656 -- Cannot create PPOConfig from given `config_dict`! Property __stdout_file__ not supported.
[2m[36m(pid=2683706)[0m DeprecationWarning: `DirectStepOptimizer` has been deprecated. This will raise an error in the future!
[2m[36m(pid=2678970)[0m DeprecationWarning: `DirectStepOptimizer` has been deprecated. This will raise an error in the future!
[2m[36m(RolloutWorker pid=2679477)[0m Exception raised in creation task: The actor died because of an error raised in its creation task, [36mray::RolloutWorker.__init__()[39m (pid=2679477, ip=172.16.100.117, actor_id=b596f763fe75d052a8b7c05801000000, repr=<ray.rllib.evaluation.rollout_worker.RolloutWorker object at 0x7f6227aa0cd0>)
[2m[36m(RolloutWorker pid=2679477)[0m   File "/home/ezhao/miniconda3/envs/MARL/lib/python3.9/site-packages/ray/rllib/evaluation/rollout_worker.py", line 397, in __init__
[2m[36m(RolloutWorker pid=2679477)[0m     self.env = env_creator(copy.deepcopy(self.env_context))
[2m[36m(RolloutWorker pid=2679477)[0m   File "/home/ezhao/code/Rllib-Unity-MARL/unity_control_PPO.py", line 171, in <lambda>
[2m[36m(RolloutWorker pid=2679477)[0m     lambda c: Unity3DEnv(
[2m[36m(RolloutWorker pid=2679477)[0m   File "/home/ezhao/code/Rllib-Unity-MARL/base_unity_env.py", line 67, in __init__
[2m[36m(RolloutWorker pid=2679477)[0m     self.unity_env = UnityEnvironment(
[2m[36m(RolloutWorker pid=2679477)[0m   File "/home/ezhao/code/Rllib-Unity-MARL/mlagents_envs/environment.py", line 215, in __init__
[2m[36m(RolloutWorker pid=2679477)[0m     self._process = env_utils.launch_executable(
[2m[36m(RolloutWorker pid=2679477)[0m   File "/home/ezhao/code/Rllib-Unity-MARL/mlagents_envs/env_utils.py", line 101, in launch_executable
[2m[36m(RolloutWorker pid=2679477)[0m     raise UnityEnvironmentException(
[2m[36m(RolloutWorker pid=2679477)[0m mlagents_envs.exception.UnityEnvironmentException: Couldn't launch the /compiled_scenes/Large_WPM_Obs_Dense/Large_WPM_Obs_Dense.x86_64 environment. Provided filename does not match any environments.
[2m[36m(pid=2683705)[0m DeprecationWarning: `DirectStepOptimizer` has been deprecated. This will raise an error in the future![32m [repeated 6x across cluster] (Ray deduplicates logs by default. Set RAY_DEDUP_LOGS=0 to disable log deduplication, or see https://docs.ray.io/en/master/ray-observability/ray-logging.html#log-deduplication for more options.)[0m
[2m[36m(RolloutWorker pid=2683705)[0m Exception raised in creation task: The actor died because of an error raised in its creation task, [36mray::RolloutWorker.__init__()[39m (pid=2683705, ip=172.16.100.117, actor_id=2dbf8e0bbdd232a9e5d0c4c601000000, repr=<ray.rllib.evaluation.rollout_worker.RolloutWorker object at 0x7ee765ecbcd0>)[32m [repeated 6x across cluster][0m
[2m[36m(RolloutWorker pid=2683705)[0m   File "/home/ezhao/miniconda3/envs/MARL/lib/python3.9/site-packages/ray/rllib/evaluation/rollout_worker.py", line 397, in __init__[32m [repeated 6x across cluster][0m
[2m[36m(RolloutWorker pid=2683705)[0m     self.env = env_creator(copy.deepcopy(self.env_context))[32m [repeated 6x across cluster][0m
[2m[36m(RolloutWorker pid=2683705)[0m   File "/home/ezhao/code/Rllib-Unity-MARL/unity_control_PPO.py", line 171, in <lambda>[32m [repeated 6x across cluster][0m
[2m[36m(RolloutWorker pid=2683705)[0m     lambda c: Unity3DEnv([32m [repeated 6x across cluster][0m
[2m[36m(RolloutWorker pid=2683705)[0m   File "/home/ezhao/code/Rllib-Unity-MARL/base_unity_env.py", line 67, in __init__[32m [repeated 6x across cluster][0m
[2m[36m(RolloutWorker pid=2683705)[0m     self.unity_env = UnityEnvironment([32m [repeated 6x across cluster][0m
[2m[36m(RolloutWorker pid=2683705)[0m   File "/home/ezhao/code/Rllib-Unity-MARL/mlagents_envs/environment.py", line 215, in __init__[32m [repeated 6x across cluster][0m
[2m[36m(RolloutWorker pid=2683705)[0m     self._process = env_utils.launch_executable([32m [repeated 6x across cluster][0m
[2m[36m(RolloutWorker pid=2683705)[0m   File "/home/ezhao/code/Rllib-Unity-MARL/mlagents_envs/env_utils.py", line 101, in launch_executable[32m [repeated 6x across cluster][0m
[2m[36m(RolloutWorker pid=2683705)[0m     raise UnityEnvironmentException([32m [repeated 6x across cluster][0m
[2m[36m(RolloutWorker pid=2683705)[0m mlagents_envs.exception.UnityEnvironmentException: Couldn't launch the /compiled_scenes/Large_WPM_Obs_Dense/Large_WPM_Obs_Dense.x86_64 environment. Provided filename does not match any environments.[32m [repeated 6x across cluster][0m
[2m[36m(PPO pid=2647792)[0m 2023-11-25 21:19:29,143	ERROR actor_manager.py:500 -- Ray error, taking actor 1 out of service. The actor died because of an error raised in its creation task, [36mray::RolloutWorker.__init__()[39m (pid=2678970, ip=172.16.100.117, actor_id=43b12a0fe5260ee3694bf4d601000000, repr=<ray.rllib.evaluation.rollout_worker.RolloutWorker object at 0x7f653bf5cd30>)
[2m[36m(PPO pid=2647792)[0m 2023-11-25 21:19:29,144	ERROR actor_manager.py:500 -- Ray error, taking actor 2 out of service. The actor died because of an error raised in its creation task, [36mray::RolloutWorker.__init__()[39m (pid=2679251, ip=172.16.100.117, actor_id=3da4b1efefab4011a94b8bee01000000, repr=<ray.rllib.evaluation.rollout_worker.RolloutWorker object at 0x7f77ecd88c10>)
[2m[36m(PPO pid=2647792)[0m 2023-11-25 21:19:29,144	ERROR actor_manager.py:500 -- Ray error, taking actor 3 out of service. The actor died because of an error raised in its creation task, [36mray::RolloutWorker.__init__()[39m (pid=2679477, ip=172.16.100.117, actor_id=b596f763fe75d052a8b7c05801000000, repr=<ray.rllib.evaluation.rollout_worker.RolloutWorker object at 0x7f6227aa0cd0>)
[2m[36m(PPO pid=2647792)[0m 2023-11-25 21:19:29,144	ERROR actor_manager.py:500 -- Ray error, taking actor 4 out of service. The actor died because of an error raised in its creation task, [36mray::RolloutWorker.__init__()[39m (pid=2679772, ip=172.16.100.117, actor_id=b66a3f55632865e46e989b6901000000, repr=<ray.rllib.evaluation.rollout_worker.RolloutWorker object at 0x7fbfa784fca0>)
[2m[36m(PPO pid=2647792)[0m 2023-11-25 21:19:29,145	ERROR actor_manager.py:500 -- Ray error, taking actor 5 out of service. The actor died because of an error raised in its creation task, [36mray::RolloutWorker.__init__()[39m (pid=2683705, ip=172.16.100.117, actor_id=2dbf8e0bbdd232a9e5d0c4c601000000, repr=<ray.rllib.evaluation.rollout_worker.RolloutWorker object at 0x7ee765ecbcd0>)
[2m[36m(PPO pid=2647792)[0m 2023-11-25 21:19:29,145	ERROR actor_manager.py:500 -- Ray error, taking actor 6 out of service. The actor died because of an error raised in its creation task, [36mray::RolloutWorker.__init__()[39m (pid=2683706, ip=172.16.100.117, actor_id=c385c8093cae2366d51dd35901000000, repr=<ray.rllib.evaluation.rollout_worker.RolloutWorker object at 0x7ee692705c10>)
[2m[36m(PPO pid=2647792)[0m 2023-11-25 21:19:29,154	ERROR actor_manager.py:500 -- Ray error, taking actor 7 out of service. The actor died because of an error raised in its creation task, [36mray::RolloutWorker.__init__()[39m (pid=2683707, ip=172.16.100.117, actor_id=5c537544383a9a6ce9eace2701000000, repr=<ray.rllib.evaluation.rollout_worker.RolloutWorker object at 0x7f4f62ea7c70>)
[2m[36m(PPO pid=2647792)[0m 2023-11-25 21:19:29,154	ERROR actor_manager.py:500 -- Ray error, taking actor 8 out of service. The actor died because of an error raised in its creation task, [36mray::RolloutWorker.__init__()[39m (pid=2683708, ip=172.16.100.117, actor_id=61ef627fd07b74a5e1c8d60501000000, repr=<ray.rllib.evaluation.rollout_worker.RolloutWorker object at 0x7f0b2677fd00>)
[2m[36m(PPO pid=2647792)[0m Exception raised in creation task: The actor died because of an error raised in its creation task, [36mray::PPO.__init__()[39m (pid=2647792, ip=172.16.100.117, actor_id=4075abd582468300b85788c201000000, repr=PPO)
[2m[36m(PPO pid=2647792)[0m   File "/home/ezhao/miniconda3/envs/MARL/lib/python3.9/site-packages/ray/rllib/evaluation/worker_set.py", line 227, in _setup
[2m[36m(PPO pid=2647792)[0m     self.add_workers(
[2m[36m(PPO pid=2647792)[0m   File "/home/ezhao/miniconda3/envs/MARL/lib/python3.9/site-packages/ray/rllib/evaluation/worker_set.py", line 593, in add_workers
[2m[36m(PPO pid=2647792)[0m     raise result.get()
[2m[36m(PPO pid=2647792)[0m   File "/home/ezhao/miniconda3/envs/MARL/lib/python3.9/site-packages/ray/rllib/utils/actor_manager.py", line 481, in __fetch_result
[2m[36m(PPO pid=2647792)[0m     result = ray.get(r)
[2m[36m(PPO pid=2647792)[0m ray.exceptions.RayActorError: The actor died because of an error raised in its creation task, [36mray::RolloutWorker.__init__()[39m (pid=2678970, ip=172.16.100.117, actor_id=43b12a0fe5260ee3694bf4d601000000, repr=<ray.rllib.evaluation.rollout_worker.RolloutWorker object at 0x7f653bf5cd30>)
[2m[36m(PPO pid=2647792)[0m 
[2m[36m(PPO pid=2647792)[0m During handling of the above exception, another exception occurred:
[2m[36m(PPO pid=2647792)[0m 
[2m[36m(PPO pid=2647792)[0m [36mray::PPO.__init__()[39m (pid=2647792, ip=172.16.100.117, actor_id=4075abd582468300b85788c201000000, repr=PPO)
[2m[36m(PPO pid=2647792)[0m     super().__init__(
[2m[36m(PPO pid=2647792)[0m     self.setup(copy.deepcopy(self.config))
[2m[36m(PPO pid=2647792)[0m   File "/home/ezhao/miniconda3/envs/MARL/lib/python3.9/site-packages/ray/rllib/algorithms/algorithm.py", line 639, in setup
[2m[36m(PPO pid=2647792)[0m     self.workers = WorkerSet(
[2m[36m(PPO pid=2647792)[0m     raise e.args[0].args[2]
2023-11-25 21:19:29,438	ERROR tune_controller.py:911 -- Trial task failed for trial PPO_unity3d_2edc6_00000
Traceback (most recent call last):
  File "/home/ezhao/miniconda3/envs/MARL/lib/python3.9/site-packages/ray/air/execution/_internal/event_manager.py", line 110, in resolve_future
    result = ray.get(future)
  File "/home/ezhao/miniconda3/envs/MARL/lib/python3.9/site-packages/ray/_private/auto_init_hook.py", line 24, in auto_init_wrapper
    return fn(*args, **kwargs)
  File "/home/ezhao/miniconda3/envs/MARL/lib/python3.9/site-packages/ray/_private/client_mode_hook.py", line 103, in wrapper
    return func(*args, **kwargs)
  File "/home/ezhao/miniconda3/envs/MARL/lib/python3.9/site-packages/ray/_private/worker.py", line 2526, in get
    raise value
ray.exceptions.RayActorError: The actor died because of an error raised in its creation task, [36mray::PPO.__init__()[39m (pid=2647792, ip=172.16.100.117, actor_id=4075abd582468300b85788c201000000, repr=PPO)
  File "/home/ezhao/miniconda3/envs/MARL/lib/python3.9/site-packages/ray/rllib/evaluation/worker_set.py", line 227, in _setup
    self.add_workers(
  File "/home/ezhao/miniconda3/envs/MARL/lib/python3.9/site-packages/ray/rllib/evaluation/worker_set.py", line 593, in add_workers
    raise result.get()
  File "/home/ezhao/miniconda3/envs/MARL/lib/python3.9/site-packages/ray/rllib/utils/actor_manager.py", line 481, in __fetch_result
    result = ray.get(r)
ray.exceptions.RayActorError: The actor died because of an error raised in its creation task, [36mray::RolloutWorker.__init__()[39m (pid=2678970, ip=172.16.100.117, actor_id=43b12a0fe5260ee3694bf4d601000000, repr=<ray.rllib.evaluation.rollout_worker.RolloutWorker object at 0x7f653bf5cd30>)
  File "/home/ezhao/miniconda3/envs/MARL/lib/python3.9/site-packages/ray/rllib/evaluation/rollout_worker.py", line 397, in __init__
    self.env = env_creator(copy.deepcopy(self.env_context))
  File "/home/ezhao/code/Rllib-Unity-MARL/unity_control_PPO.py", line 171, in <lambda>
    lambda c: Unity3DEnv(
  File "/home/ezhao/code/Rllib-Unity-MARL/base_unity_env.py", line 67, in __init__
    self.unity_env = UnityEnvironment(
  File "/home/ezhao/code/Rllib-Unity-MARL/mlagents_envs/environment.py", line 215, in __init__
    self._process = env_utils.launch_executable(
  File "/home/ezhao/code/Rllib-Unity-MARL/mlagents_envs/env_utils.py", line 101, in launch_executable
    raise UnityEnvironmentException(
mlagents_envs.exception.UnityEnvironmentException: Couldn't launch the /compiled_scenes/Large_WPM_Obs_Dense/Large_WPM_Obs_Dense.x86_64 environment. Provided filename does not match any environments.

During handling of the above exception, another exception occurred:

[36mray::PPO.__init__()[39m (pid=2647792, ip=172.16.100.117, actor_id=4075abd582468300b85788c201000000, repr=PPO)
  File "/home/ezhao/miniconda3/envs/MARL/lib/python3.9/site-packages/ray/rllib/algorithms/algorithm.py", line 517, in __init__
    super().__init__(
  File "/home/ezhao/miniconda3/envs/MARL/lib/python3.9/site-packages/ray/tune/trainable/trainable.py", line 169, in __init__
    self.setup(copy.deepcopy(self.config))
  File "/home/ezhao/miniconda3/envs/MARL/lib/python3.9/site-packages/ray/rllib/algorithms/algorithm.py", line 639, in setup
    self.workers = WorkerSet(
  File "/home/ezhao/miniconda3/envs/MARL/lib/python3.9/site-packages/ray/rllib/evaluation/worker_set.py", line 179, in __init__
    raise e.args[0].args[2]
mlagents_envs.exception.UnityEnvironmentException: Couldn't launch the /compiled_scenes/Large_WPM_Obs_Dense/Large_WPM_Obs_Dense.x86_64 environment. Provided filename does not match any environments.
2023-11-25 21:19:29,450	ERROR tune.py:1144 -- Trials did not complete: [PPO_unity3d_2edc6_00000]
2023-11-25 21:19:29,468	WARNING experiment_analysis.py:916 -- Failed to read the results for 1 trials:
- /home/ezhao/ray_results/PPO/PPO_unity3d_2edc6_00000_0_2023-11-25_21-18-07
[2m[36m(RolloutWorker pid=2683708)[0m Exception raised in creation task: The actor died because of an error raised in its creation task, [36mray::RolloutWorker.__init__()[39m (pid=2683708, ip=172.16.100.117, actor_id=61ef627fd07b74a5e1c8d60501000000, repr=<ray.rllib.evaluation.rollout_worker.RolloutWorker object at 0x7f0b2677fd00>)
[2m[36m(PPO pid=2647792)[0m   File "/home/ezhao/miniconda3/envs/MARL/lib/python3.9/site-packages/ray/rllib/evaluation/worker_set.py", line 179, in __init__[32m [repeated 13x across cluster][0m
[2m[36m(PPO pid=2647792)[0m     self.env = env_creator(copy.deepcopy(self.env_context))[32m [repeated 10x across cluster][0m
[2m[36m(PPO pid=2647792)[0m   File "/home/ezhao/code/Rllib-Unity-MARL/unity_control_PPO.py", line 171, in <lambda>[32m [repeated 10x across cluster][0m
[2m[36m(PPO pid=2647792)[0m     lambda c: Unity3DEnv([32m [repeated 10x across cluster][0m
[2m[36m(PPO pid=2647792)[0m   File "/home/ezhao/code/Rllib-Unity-MARL/base_unity_env.py", line 67, in __init__[32m [repeated 10x across cluster][0m
[2m[36m(PPO pid=2647792)[0m     self.unity_env = UnityEnvironment([32m [repeated 10x across cluster][0m
[2m[36m(PPO pid=2647792)[0m   File "/home/ezhao/code/Rllib-Unity-MARL/mlagents_envs/environment.py", line 215, in __init__[32m [repeated 10x across cluster][0m
[2m[36m(PPO pid=2647792)[0m     self._process = env_utils.launch_executable([32m [repeated 10x across cluster][0m
[2m[36m(PPO pid=2647792)[0m   File "/home/ezhao/code/Rllib-Unity-MARL/mlagents_envs/env_utils.py", line 101, in launch_executable[32m [repeated 10x across cluster][0m
[2m[36m(PPO pid=2647792)[0m     raise UnityEnvironmentException([32m [repeated 10x across cluster][0m
[2m[36m(PPO pid=2647792)[0m mlagents_envs.exception.UnityEnvironmentException: Couldn't launch the /compiled_scenes/Large_WPM_Obs_Dense/Large_WPM_Obs_Dense.x86_64 environment. Provided filename does not match any environments.[32m [repeated 11x across cluster][0m
╭────────────────────────────────────────────────────────╮
│ Configuration for experiment     PPO                   │
├────────────────────────────────────────────────────────┤
│ Search algorithm                 BasicVariantGenerator │
│ Scheduler                        FIFOScheduler         │
│ Number of trials                 1                     │
╰────────────────────────────────────────────────────────╯

View detailed results here: /home/ezhao/ray_results/PPO
To visualize your results with TensorBoard, run: `tensorboard --logdir /home/ezhao/ray_results/PPO`

Trial status: 1 PENDING
Current time: 2023-11-25 21:18:07. Total running time: 0s
Logical resource usage: 0/10 CPUs, 0/1 GPUs (0.0/1.0 accelerator_type:RTX)
╭────────────────────────────────────╮
│ Trial name                status   │
├────────────────────────────────────┤
│ PPO_unity3d_2edc6_00000   PENDING  │
╰────────────────────────────────────╯

Trial status: 1 PENDING
Current time: 2023-11-25 21:18:37. Total running time: 30s
Logical resource usage: 9.0/10 CPUs, 1.0/1 GPUs (0.0/1.0 accelerator_type:RTX)
╭────────────────────────────────────╮
│ Trial name                status   │
├────────────────────────────────────┤
│ PPO_unity3d_2edc6_00000   PENDING  │
╰────────────────────────────────────╯

Trial status: 1 PENDING
Current time: 2023-11-25 21:19:07. Total running time: 1min 0s
Logical resource usage: 9.0/10 CPUs, 1.0/1 GPUs (0.0/1.0 accelerator_type:RTX)
╭────────────────────────────────────╮
│ Trial name                status   │
├────────────────────────────────────┤
│ PPO_unity3d_2edc6_00000   PENDING  │
╰────────────────────────────────────╯

Trial status: 1 ERROR
Current time: 2023-11-25 21:19:29. Total running time: 1min 22s
Logical resource usage: 0/10 CPUs, 0/1 GPUs (0.0/1.0 accelerator_type:RTX)
╭────────────────────────────────────╮
│ Trial name                status   │
├────────────────────────────────────┤
│ PPO_unity3d_2edc6_00000   ERROR    │
╰────────────────────────────────────╯

Number of errored trials: 1
╭──────────────────────────────────────────────────────────────────────────────────────────────────────────────────────────────╮
│ Trial name                  # failures   error file                                                                          │
├──────────────────────────────────────────────────────────────────────────────────────────────────────────────────────────────┤
│ PPO_unity3d_2edc6_00000              1   /home/ezhao/ray_results/PPO/PPO_unity3d_2edc6_00000_0_2023-11-25_21-18-07/error.txt │
╰──────────────────────────────────────────────────────────────────────────────────────────────────────────────────────────────╯

